Workbook
Name BAGVI: 'C'!$C$9:$F$381
Name BAGVI: D!$EN$5:$EQ$269
Name OLE_LINK1: #REF!

Sheet اندراج
A1: عمق افق | C1: STD | D1: طول بلد | E1: عرض بلد | F1: مطلوبہ مقام کانام
A2: 0 | C2: 5 | D2: -72 | E2: 34 | F2: مردان
D3: 11 | E3: 19
H7: =0.3313*60 -> 19.878
H8: =0.198*60 -> 11.88
A222: 29.50N | B222: 75.10E | C222: 162 Batumi | D222: 41-12 N | E222: 41-00 E | F222: Band,A.K. | G222: 33:31 | I222: 73:32
A223: 27.20N | B223: 67.58E | C223: 163 Bauchi | D223: 10-30 N | E223: 9-57 E | F223: Band Rahim'yk | G223: 28:19 | I223: 69:43
A224: 35.29N | B224: 68.01E | C224: 164 Beijing | D224: 40-00 N | E224: 16-00 E | F224: Band,Sukkur | G224: 28:3 | I224: 69:22
A225: 34.28N | B225: 72.22E | C225: 165 Beira | D225: 19-00 S | E225: 35-00 E | F225: Band Alipur.Multan | G225: 29:33 | I225: 71:26
A226: 26.03N | B226: 73.12E | C226: 166 Beirut | D226: 34-15 N | E226: 35-00 E | F226: Band Kili,Mohmand | G226: 34:28 | I226: 71:17
A227: 28.35N | B227: 63.03E | C227: 167 Bejaia | D227: 36-30 N | E227: 5-00 E | F227: Band Kurai,D.I.Khan | G227: 32:2 | I227: 70:54
A228: 25.26N | B228: 68.31E | C228: 168 Belcher Is | D228: 56-32 N | E228: 81-00 W | F228: Band Mahi,-Nosh'froz | G228: 27:1 | I228: 68:1
A229: 27.45N | B229: 70.24E | C229: 169 Belem | D229: 91-18 S | E229: 48-27 W | F229: Band Murad Khan,K'chi | G229: 25:5 | I229: 67:0
A230: 33.58N | B230: 68.45E | C230: 170 Belfast | D230: 55-00 N | E230: 5-55 W | F230: Band Virah,Dadu | G230: 25:35 | I230: 68:4
A231: 33.48N | B231: 73.49E | C231: 171 Belgaum | D231: 15-30 N | E231: 74-46 E | F231: Balda,Bajour | G231: 34:48 | I231: 71:36
A232: 31.12N | B232: 70.46E | C232: 172 Belgium | D232: 50-00 N | E232: 4-00 E | F232: Banda,Bajour | G232: 34:38 | I232: 71:43
A233: 33.56N | B233: 72.21E | C233: 173 Belgrade | D233: 44-56 N | E233: 20-30 E | F233: Banda,Dir | G233: 34:56 | I233: 71:53
... A305: 34.05N | B305: 71.29E | C305: 245 Brunette Downs | D305: 18-36 S | E305: 136-00 E | F305: Basti Wadja,- D.I.Khan | G305: 29:43 | I305: 70:39
A306: 36.53N | B306: 73.21E | C306: 246 Brussles | D306: 51-00 N | E306: 4-25 E | F306: Basti Wall Mohd.,Jhang | G306: 30.37 | I306: 71:47
A307: 31.13N | B307: 75.10E | C307: 247 Bryansk | D307: 50-54 N | E307: 4-29 E | F307: Basti Walwat,Mzfr'srh | G307: 29:12 | I307: 70:38
A308: 35.06N | B308: 73.37E | C308: 248 Bucaranianga | D308: 7-00 N | E308: 71-12 W | F308: Basti Wa am,Multan | G308: 30:29 | I308: 71:46
A309: 33.20N | B309: 74.15E | C309: 249 Bucharest | D309: 44-00 N | E309: 26-00 E | F309: Basti Yakiam,- D.I.Khan | G309: 29:51 | I309: 70:40
A310: 25.18N | B310: 73.56E | C310: 250 Buenaventura | D310: 3-52 N | E310: 77-00 W | F310: Basu Kali,Kurrum | G310: 33:49 | I310: 70:0
A311: 33.36N | B311: 62.33E | C311: 251 Buenos Aires | D311: 35-00 S | E311: 58-32 W | F311: Beli,Sialkot | G311: 32:43 | I311: 74:33
A312: 34.12N | B312: 74.26E | C312: 252 Bujumbura | D312: 4-00 S | E312: 29-00 E | F312: Beliwala,D.I.Khan | G312: 32:3 | I312: 70:58
A313: 25.58N | B313: 74.21E | C313: 253 Bulagan | D313: 49-08 N | E313: 103-17 E | F313: Beliwala,Jhan9 | G313: 31:14 | I313: 72:17
A314: 26.59N | B314: 67.29E | C314: 254 Bulawayo | D314: 20-02 S | E314: 28-46 E | F314: Bell at,Nasirabad | G314: 28:59 | I314: 68:0
A315: 31.47N | B315: 66.20E | C315: 255 Bulgaria | D315: 44-00 N | E315: 25-00 E | F315: Belo Gaji,-Nosh'froz | G315: 27:17 | I315: 68:11
A316: 25.06N | B316: 72.36E | C316: 256 Burdum | D316: 15-31 S | E316: 33-20 E | F316: Belsa,Gujrat | G316: 32:55 | I316: 73:54
A317: 35.14N | B317: 69.34E | C317: 257 Burgos | D317: 42-28 N | E317: 3-41 W | F317: Bemarai,Dir | G317: 34:49 | I317: 71:44
A318: 29.39N | B318: 72.34E | C318: 258 Burketown | D318: 15-40 S | E318: 139-30 E | F318: Beor,A.K. | G318: 33:35 | I318: 73:34
A319: 30.38N | B319: 67.19E | C319: 259 Burma | D319: 21-00 N | E319: 93-00 E | F319: Beorai,Chitral | G319: 35:28 | I319: 71:41
A320: 35.06N | B320: 68.48E | C320: 260 Burrundie | D320: 13-31 S | E320: 131-42 E | F320: Ber,D.I.Khan | G320: 31.21 | I320: 70:10
A321: 32.58N | B321: 71.46E | C321: 261 Bursa | D321: 40-03 N | E321: 29-00 E | F321: Ber,Larkana - | G321: 27:34 | I321: 67:56
A322: 36.05N | B322: 74.40E | C322: 262 Buru | D322: 3-30 S | E322: 126-30 E | F322: Ber Band,Mzfrgrh | G322: 29:38 | I322: 70:59
A323: 27.28N | B323: 72.04E | C323: 263 Burundj | D323: 3-25 S | E323: 29-26 E | F323: Bera,Shikhu'pra | G323: 31:47 | I323: 74:6
A324: 34.13N | B324: 69.02E | C324: 264 Bushehr | D324: 29-00 N | E324: 51-00 E | F324: Berai,Bannu | G324: 32:57 | I324: 70:55
A325: 30.33N | B325: 77.17E | C325: 265 Buta | D325: 2-45 N | E325: 25-00 E | F325: Berai Kot,WANA | G325: 32:57 | I325: 70:4
A326: 28.02N | B326: 71.27E | C326: 266 Batumj | D326: 41-35 N | E326: 41-20 E | F326: Berala,Kohat | G326: 33:25 | I326: 70:30
A327: 34.40N | B327: 67.28E | C327: 267 Butung | D327: 6-00 S | E327: 23-16 E | F327: Beramena,Psh'wr | G327: 34:19 | I327: 71:27
...

Sheet برائے طلباء
A1: =اندراج!$F$2 -> مردان | G1: دائمی اوقات نماز ودائمی سحروافطار برائے | N1: =اندراج!$F$2 -> مردان | T1: دائمی اوقات نماز ودائمی سحروافطار برائے | AA1: =اندراج!$F$2 -> مردان | AG1: دائمی اوقات نماز ودائمی سحروافطار برائے | AN1: =اندراج!$F$2 -> مردان | AT1: دائمی اوقات نماز ودائمی سحروافطار برائے | BA1: =اندراج!$F$2 -> مردان | BG1: دائمی اوقات نماز ودائمی سحروافطار برائے | BN1: =اندراج!$F$2 -> مردان | BT1: دائمی اوقات نماز ودائمی سحروافطار برائے | CA1: =اندراج!$F$2 -> مردان | CG1: دائمی اوقات نماز ودائمی سحروافطار برائے | CN1: =اندراج!$F$2 -> مردان | CT1: دائمی اوقات نماز ودائمی سحروافطار برائے | DA1: =اندراج!$F$2 -> مردان | DG1: دائمی اوقات نماز ودائمی سحروافطار برائے | DN1: =اندراج!$F$2 -> مردان | DT1: دائمی اوقات نماز ودائمی سحروافطار برائے | EA1: =اندراج!$F$2 -> مردان | EG1: دائمی اوقات نماز ودائمی سحروافطار برائے | EN1: =اندراج!$F$2 -> مردان | ET1: دائمی اوقات نماز ودائمی سحروافطار برائے
A4: شفق ابیض | B4: شفق احمر | C4: افطار | D4: غروب | E4: مثل ثانی | F4: مثل اول | G4: نصف النھار عرفی | H4: نصف النھار شرعی | I4: شروق | J4: طلوع آفتاب | K4: صبح صادق | L4: ختم سحر | M4: دسمبر | N4: شفق ابیض | O4: شفق احمر | P4: افطار | Q4: غروب | R4: مثل ثانی | S4: مثل اول | T4: نصف النھار عرفی | U4: نصف النھار شرعی | V4: شروق | W4: طلوع آفتاب | X4: صبح صادق | Y4: ختم سحر | Z4: نومبر | AA4: شفق ابیض | AB4: شفق احمر | AC4: افطار | AD4: غروب | AE4: مثل ثانی | AF4: مثل اول | AG4: نصف النھار عرفی | AH4: نصف النھار شرعی | AI4: شروق | AJ4: طلوع آفتاب | AK4: صبح صادق | AL4: ختم سحر | AM4: اکتوبر | AN4: شفق ابیض | AO4: شفق احمر | AP4: افطار | AQ4: غروب | AR4: عصر2 | AS4: مثل اول | AT4: نصف النھار عرفی | AU4: نصف النھار شرعی | AV4: شروق | AW4: طلوع آفتاب | AX4: صبح صادق | AY4: ختم سحر | AZ4: ستمبر | BA4: شفق ابیض | BB4: شفق احمر | BC4: افطار | BD4: غروب | BE4: مثل ثانی | BF4: مثل اول | BG4: نصف النھار عرفی | BH4: نصف النھار شرعی | BI4: شروق | BJ4: طلوع آفتاب | BK4: صبح صادق | BL4: ختم سحر | BM4: اگست | BN4: شفق ابیض | BO4: شفق احمر | BP4: افطار | BQ4: غروب | BR4: مثل ثانی | BS4: مثل اول | BT4: نصف النھار عرفی | BU4: نصف النھار شرعی | BV4: شروق | BW4: طلوع آفتاب | BX4: صبح صادق | BY4: ختم سحر | BZ4: جولائی | CA4: شفق ابیض | CB4: شفق احمر | CC4: افطار | CD4: غروب | CE4: مثل ثانی | CF4: مثل اول | CG4: نصف النھار عرفی | CH4: نصف النھار شرعی | CI4: شروق | CJ4: طلوع آفتاب | CK4: صبح صادق | CL4: ختم سحر | CM4: جون | CN4: شفق ابیض | CO4: شفق احمر | CP4: افطار | CQ4: غروب | CR4: مثل ثانی | CS4: مثل اول | CT4: نصف النھار عرفی | CU4: نصف النھار شرعی | CV4: شروق | CW4: طلوع آفتاب | CX4: صبح صادق | CY4: ختم سحر | CZ4: مئی | DA4: شفق ابیض | DB4: شفق احمر | DC4: افطار | DD4: غروب | DE4: مثل ثانی | DF4: مثل اول | DG4: نصف النھار عرفی | DH4: نصف النھار شرعی | DI4: شروق | DJ4: طلوع آفتاب | DK4: صبح صادق | DL4: ختم سحر | DM4: اپریل | DN4: شفق ابیض | DO4: شفق احمر | DP4: افطار | DQ4: غروب | DR4: مثل ثانی | DS4: مثل اول | DT4: نصف النھار عرفی | DU4: نصف النھار شرعی | DV4: شروق | DW4: طلوع آفتاب | DX4: صبح صادق | DY4: ختم سحر | DZ4: مارچ | EA4: شفق ابیض | EB4: شفق احمر | EC4: افطار | ED4: غروب | EE4: مثل ثانی | EF4: مثل اول | EG4: نصف النھار عرفی | EH4: نصف النھار شرعی | EI4: شروق | EJ4: طلوع آفتاب | EK4: صبح صادق | EL4: ختم سحر | EM4: فروری | EN4: شفق ابیض | EO4: شفق احمر | EP4: افطار | EQ4: غروب | ER4: مثل ثانی | ES4: مثل اول | ET4: نصف النھار عرفی | EU4: نصف النھار شرعی | EV4: شروق | EW4: طلوع آفتاب | EX4: صبح صادق | EY4: ختم سحر | EZ4: جنوری
A5: =(IF(AND(D!FC222<180),D!FG222+(D!FE222/15-12),0))/24 -> 0.27084935 | B5: =(IF(AND(D!FA222<180),D!FG222+(D!FA222/15-12),0))/24 -> 0.2498007 | C5: =TIME(HOUR(D5),MINUTE(D5)+3,SECOND(D5)) -> 0.21128472 | D5: =(IF(AND(D!$EY222<180),D!$FG222+(D!$EY222/15-12),0))/24 -> 0.20920198 | E5: =(IF(AND(D!$ER222<180),D!$FG222+(D!$ER222/15-12),0))/24 -> 0.14114246 | F5: =(IF(AND(D!$ET222<180),D!$FG222+(D!$ET222/15-12),0))/24 -> 0.11291307 | G5: =D!FG222/24 -> 0.50019907 | H5: =(K5+(D!FK222/2)) -> 0.46937539 | I5: =(IF(AND(D!$EW222<180),D!$FG222-(D!$EW222/15),0))/24 -> 0.29962569 | J5: =(IF(AND(D!$EY222<180),D!$FG222-(D!$EY222/15),0))/24 -> 0.29119617 | K5: =(IF(AND(D!$FC222<180),D!$FG222-(D!$FE222/15),0))/24 -> 0.2295488 | L5: =TIME(HOUR(K5),MINUTE(K5)-5,MINUTE(K5)) -> 0.22604167 | M5: 1 | N5: =(IF(AND(D!FZ222<180),D!GD222+(D!GB222/15-12),0))/24 -> 0.27998265 | O5: =(IF(AND(D!FX222<180),D!GD222+(D!FX222/15-12),0))/24 -> 0.25962131 | P5: =TIME(HOUR(Q5),MINUTE(Q5)+3,SECOND(Q5)) -> 0.22309028 | Q5: =(IF(AND(D!$FU222<180),D!$GD222+(D!$FU222/15-12),0))/24 -> 0.22100159 | R5: =(IF(AND(D!$FN222<180),D!$GD222+(D!$FN222/15-12),0))/24 -> 0.15254101 | S5: =(IF(AND(D!$FP222<180),D!$GD222+(D!$FP222/15-12),0))/24 -> 0.12172527 | T5: =D!GD222/24 -> 0.49640741 | U5: =(X5+(D!GG222/2)) -> 0.46691688 | V5: =(IF(AND(D!$FS222<180),D!$GD222-(D!$FS222/15),0))/24 -> 0.27970606 | W5: =(IF(AND(D!$FU222<180),D!$GD222-(D!$FU222/15),0))/24 -> 0.27181323 | X5: =(IF(AND(D!$FZ222<180),D!$GD222-(D!$GB222/15),0))/24 -> 0.21283217 | Y5: =TIME(HOUR(X5),MINUTE(X5)-5,MINUTE(X5)) -> 0.20909722 | Z5: 1 | AA5: =(IF(AND(D!FC180<180),D!FG180+(D!FE180/15-12),0))/24 -> 0.30496458 | AB5: =(IF(AND(D!FA180<180),D!FG180+(D!FA180/15-12),0))/24 -> 0.28465749 | AC5: =TIME(HOUR(AD5),MINUTE(AD5)+3,SECOND(AD5)) -> 0.24915509 | AD5: =(IF(AND(D!$EY180<180),D!$FG180+(D!$EY180/15-12),0))/24 -> 0.24707215 | AE5: =(IF(AND(D!$ER180<180),D!$FG180+(D!$ER180/15-12),0))/24 -> 0.17606365 | AF5: =(IF(AND(D!$ET180<180),D!$FG180+(D!$ET180/15-12),0))/24 -> 0.14090778 | AG5: =D!FG180/24 -> 0.50061574 | AH5: =(AK5+(D!FK180/2)) -> 0.47166952 | AI5: =(IF(AND(D!$EW180<180),D!$FG180-(D!$EW180/15),0))/24 -> 0.26169024 | AJ5: =(IF(AND(D!$EY180<180),D!$FG180-(D!$EY180/15),0))/24 -> 0.25415933 | AK5: =(IF(AND(D!$FC180<180),D!$FG180-(D!$FE180/15),0))/24 -> 0.1962669 | AL5: =TIME(HOUR(AK5),MINUTE(AK5)-10,MINUTE(AK5)) -> 0.189375 | AM5: 1 | AN5: =(IF(AND(D!FZ180<180),D!GD180+(D!GB180/15-12),0))/24 -> 0.33666029 | AO5: =(IF(AND(D!FX180<180),D!GD180+(D!FX180/15-12),0))/24 -> 0.31501878 | AP5: =TIME(HOUR(AQ5),MINUTE(AQ5)+3,SECOND(AQ5)) -> 0.27827546 | AQ5: =(IF(AND(D!$FU180<180),D!$GD180+(D!$FU180/15-12),0))/24 -> 0.27619649 | AR5: =(IF(AND(D!$FN180<180),D!$GD180+(D!$FN180/15-12),0))/24 -> 0.19954038 | AS5: =(IF(AND(D!$FP180<180),D!$GD180+(D!$FP180/15-12),0))/24 -> 0.15865999 | AT5: =D!GD180/24 -> 0.50782407 | AU5: =(AX5+(D!GG180/2)) -> 0.47759217 | AV5: =(IF(AND(D!$FS180<180),D!$GD180-(D!$FS180/15),0))/24 -> 0.24706977 | AW5: =(IF(AND(D!$FU180<180),D!$GD180-(D!$FU180/15),0))/24 -> 0.23945166 | AX5: =(IF(AND(D!$FZ180<180),D!$GD180-(D!$GB180/15),0))/24 -> 0.17898786 | AY5: =TIME(HOUR(AX5),MINUTE(AX5)-10,MINUTE(AX5)) -> 0.17172454 | AZ5: 1 | BA5: =(IF(AND(D!FC138<180),D!FG138+(D!FE138/15-12),0))/24 -> 0.3674242 | BB5: =(IF(AND(D!FA138<180),D!FG138+(D!FA138/15-12),0))/24 -> 0.34286753 | BC5: =TIME(HOUR(BD5),MINUTE(BD5)+3,SECOND(BD5)) -> 0.3027662 | BD5: =(IF(AND(D!$EY138<180),D!$FG138+(D!$EY138/15-12),0))/24 -> 0.30068207 | BE5: =(IF(AND(D!$ER138<180),D!$FG138+(D!$ER138/15-12),0))/24 -> 0.21581082 | BF5: =(IF(AND(D!$ET138<180),D!$FG138+D!$ET138/15-12,0))/24 -> 0.16819909 | BG5: =D!FG138/24 -> 0.51228241 | BH5: =(BK5+(D!FK138/2)) -> 0.47891134 | BI5: =(IF(AND(D!$EW138<180),D!$FG138-(D!$EW138/15),0))/24 -> 0.23196249 | BJ5: =(IF(AND(D!$EY138<180),D!$FG138-(D!$EY138/15),0))/24 -> 0.22388274 | BK5: =(IF(AND(D!$FC138<180),D!$FG138-(D!$FE138/15),0))/24 -> 0.15714061 | BL5: =TIME(HOUR(BK5),MINUTE(BK5)-10,MINUTE(BK5)) -> 0.15053241 | BM5: 1 | BN5: =(IF(AND(D!FZ138<180),D!GD138+(D!GB138/15-12),0))/24 -> 0.38338981 | BO5: =(IF(AND(D!FX138<180),D!GD138+(D!FX138/15-12),0))/24 -> 0.35599812 | BP5: =TIME(HOUR(BQ5),MINUTE(BQ5)+3,SECOND(BQ5)) -> 0.31278935 | BQ5: =(IF(AND(D!$FU138<180),D!$GD138+(D!$FU138/15-12),0))/24 -> 0.31070716 | BR5: =(IF(AND(D!$FN138<180),D!$GD138+(D!$FN138/15-12),0))/24 -> 0.21968543 | BS5: =(IF(AND(D!$FP138<180),D!$GD138+(D!$FP138/15-12),0))/24 -> 0.16746202 | BT5: =D!GD138/24 -> 0.51057407 | BU5: =(BX5+(D!GG138/2)) -> 0.47423275 | BV5: =(IF(AND(D!$FS138<180),D!$GD138-(D!$FS138/15),0))/24 -> 0.21895526 | BW5: =(IF(AND(D!$FU138<180),D!$GD138-(D!$FU138/15),0))/24 -> 0.21044099 | BX5: =(IF(AND(D!$FZ138<180),D!$GD138-(D!$GB138/15),0))/24 -> 0.13775834 | BY5: =TIME(HOUR(BX5),MINUTE(BX5)-10,MINUTE(BX5)) -> 0.13076389 | BZ5: 1 | CA5: =(IF(AND(D!FC97<180),D!FG97+D!FE97/15-12,0))/24 -> 0.37559553 | CB5: =(IF(AND(D!FA97<180),D!FG97+D!FA97/15-12,0))/24 -> 0.3488403 | CC5: =TIME(HOUR(CD5),MINUTE(CD5)+3,SECOND(CD5)) -> 0.30630787 | CD5: =(IF(AND(D!$EY97<180),D!$FG97+(D!$EY97/15-12),0))/24 -> 0.30422429 | CE5: =(IF(AND(D!$ER97<180),D!$FG97+(D!$ER97/15-12),0))/24 -> 0.21446883 | CF5: =(IF(AND(D!$ET97<180),D!$FG97+(D!$ET97/15-12),0))/24 -> 0.16317572 | CG5: =D!FG97/24 -> 0.50636574 | CH5: =(CK5+(D!FK97/2)) -> 0.47068012 | CI5: =(IF(AND(D!$EW97<180),D!$FG97-(D!$EW97/15),0))/24 -> 0.21692787 | CJ5: =(IF(AND(D!$EY97<180),D!$FG97-(D!$EY97/15),0))/24 -> 0.20850719 | CK5: =(IF(AND(D!$FC97<180),D!$FG97-(D!$FE97/15),0))/24 -> 0.13713595 | CL5: =TIME(HOUR(CK5),MINUTE(CK5)-10,MINUTE(CK5)) -> 0.13005787 | CM5: 1 | CN5: =(IF(AND(D!FZ97<180),D!GD97+(D!GB97/15-12),0))/24 -> 0.35295659 | CO5: =(IF(AND(D!FX97<180),D!GD97+(D!FX97/15-12),0))/24 -> 0.32944722 | CP5: =TIME(HOUR(CQ5),MINUTE(CQ5)+3,SECOND(CQ5)) -> 0.29054398 | CQ5: =(IF(AND(D!$FU97<180),D!$GD97+(D!$FU97/15-12),0))/24 -> 0.28846501 | CR5: =(IF(AND(D!$FN97<180),D!$GD97+(D!$FN97/15-12),0))/24 -> 0.20625667 | CS5: =(IF(AND(D!$FP97<180),D!$GD97+(D!$FP97/15-12),0))/24 -> 0.16073145 | CT5: =D!GD97/24 -> 0.50582407 | CU5: =(CX5+(D!GG97/2)) -> 0.47954339 | CV5: =(IF(AND(D!$FS97<180),D!$GD97-(D!$FS97/15),0))/24 -> 0.23109364 | CW5: =(IF(AND(D!$FU97<180),D!$GD97-(D!$FU97/15),0))/24 -> 0.22318314 | CX5: =(IF(AND(D!$FZ97<180),D!$GD97-(D!$FZ97/15),0))/24 -> 0.17062177 | CY5: =TIME(HOUR(CX5),MINUTE(CX5)-10,MINUTE(CX5)) -> 0.16325231 | CZ5: 1 | DA5: =(IF(AND(D!FC51<180),D!FG51+(D!FC51/15-12),0))/24 -> 0.32089388 | DB5: =(IF(AND(D!FA51<180),D!FG51+(D!FA51/15-12),0))/24 -> 0.31042681 | DC5: =TIME(HOUR(DD5),MINUTE(DD5)+3,SECOND(DD5)) -> 0.27431713 | DD5: =(IF(AND(D!$EY51<180),D!$FG51+(D!$EY51/15-12),0))/24 -> 0.27223423 | DE5: =(IF(AND(D!$ER51<180),D!$FG51+(D!$ER51/15-12),0))/24 -> 0.19764749 | DF5: =(IF(AND(D!$ET51<180),D!$FG51+(D!$ET51/15-12),0))/24 -> 0.1586714 | DG5: =D!FG51/24 -> 0.51049074 | DH5: =(DK5+(D!FK51/2)) -> 0.48086211 | DI5: =(IF(AND(D!$EW51<180),D!$FG51-(D!$EW51/15),0))/24 -> 0.25629215 | DJ5: =(IF(AND(D!$EY51<180),D!$FG51-(D!$EY51/15),0))/24 -> 0.24874725 | DK5: =(IF(AND(D!$FC51<180),D!$FG51-(D!$FE51/15),0))/24 -> 0.18948999 | DL5: =TIME(HOUR(DK5),MINUTE(DK5)-10,MINUTE(DK5)) -> 0.18231481 | DM5: 1 | DN5: =(IF(AND(D!FZ51<180),D!GD51+D!GB51/15-12,0))/24 -> 0.31370136 | DO5: =(IF(AND(D!FX51<180),D!GD51+D!FX51/15-12,0))/24 -> 0.2926729 | DP5: =TIME(HOUR(DQ5),MINUTE(DQ5)+3,SECOND(DQ5)) -> 0.25704861 | DQ5: =(IF(AND(D!$EY51<180),D!GD51+(D!FU51/15-12),0))/24 -> 0.25496471 | DR5: =(IF(AND(D!$FN51<180),D!GD51+(D!FN51/15-12),0))/24 -> 0.18518414 | DS5: =(IF(AND(D!$FP51<180),D!GD51+(D!FP51/15-12),0))/24 -> 0.15170901 | DT5: =D!GD51/24 -> 0.51632407 | DU5: =(DX5+(D!GG51/2)) -> 0.48695575 | DV5: =(IF(AND(D!FS51<180),D!GD51-(D!FS51/15),0))/24 -> 0.28529177 | DW5: =(IF(AND(D!FU51<180),D!GD51-(D!FU51/15),0))/24 -> 0.27768344 | DX5: =(IF(AND(D!$FC51<180),D!GD51-(D!GB51/15),0))/24 -> 0.21894679 | DY5: =TIME(HOUR(DX5),MINUTE(DX5)-10,MINUTE(DX5)) -> 0.21197917 | DZ5: 1 | EA5: =(IF(AND(D!$FC6<180),D!$FG6+D!$FE6/15-12,0))/24 -> 0.29632487 | EB5: =(IF(AND(D!$FA6<180),D!$FG6+D!$FA6/15-12,0))/24 -> 0.27578821 | EC5: =TIME(HOUR(ED5),MINUTE(ED5)+3,SECOND(ED5)) -> 0.2387037 | ED5: =(IF(AND(D!$EY6<180),D!FG6+(D!$EY6/15-12),0))/24 -> 0.23662035 | EE5: =(IF(AND(D!$ER6<180),D!FG6+(D!$ER6/15-12),0))/24 -> 0.16839941 | EF5: =(IF(AND(D!$ET6<180),D!FG6+(D!$ET6/15-12),0))/24 -> 0.13847363 | EG5: =D!$FG6/24 -> 0.51719907 | EH5: =($EK5+(D!$FK6/2)) -> 0.48734681 | EI5: =(IF(AND(D!$EW6<180),D!FG6-(D!$EW6/15),0))/24 -> 0.30582276 | EJ5: =(IF(AND(D!$EY6<180),D!$FG6-(D!$EY6/15),0))/24 -> 0.2977778 | EK5: =(IF(AND(D!$FC6<180),D!$FG6-(D!$FE6/15),0))/24 -> 0.23807328 | EL5: =TIME(HOUR(EK5),MINUTE(EK5)-10,MINUTE(EK5)) -> 0.23104167 | EM5: 1 | EN5: =(IF(AND(D!FZ6<180),D!GD6+(D!GB6/15-12),0))/24 -> 0.27885274 | EO5: =(IF(AND(D!$FX6<180),D!$GD6+(D!$FX6/15-12),0))/24 -> 0.25764789 | EP5: =TIME(HOUR(EQ5),MINUTE(EQ5)+3,SECOND(EQ5)) -> 0.21871528 | EQ5: =(IF(AND(D!$FU6<180),D!$GD6+(D!$FU6/15-12),0))/24 -> 0.21663141 | ER5: =(IF(AND(D!$FN6<180),D!$GD6+(D!$FN6/15-12),0))/24 -> 0.14855651 | ES5: =(IF(AND(D!$FP6<180),D!$GD6+(D!$FP6/15-12),0))/24 -> 0.12073196 | ET5: =D!$GD6/24 -> 0.51019907 | EU5: =($EX5+(D!$GG6/2)) -> 0.47908841 | EV5: =(IF(AND(D!$FS6<180),D!$GD6-(D!$FS6/15),0))/24 -> 0.31230738 | EW5: =(IF(AND(D!$FU6<180),D!$GD6-(D!$FU6/15),0))/24 -> 0.30376674 | EX5: =(IF(AND(D!$FZ6<180),D!$GD6-(D!$GB6/15),0))/24 -> 0.2415454 | EY5: =TIME(HOUR(EX5),MINUTE(EX5)-5,MINUTE(EX5)) -> 0.23804398 | EZ5: 1
A6: =(IF(AND(D!FC223<180),D!FG223+(D!FE223/15-12),0))/24 -> 0.27083607 | B6: =(IF(AND(D!FA223<180),D!FG223+(D!FA223/15-12),0))/24 -> 0.24976762 | C6: =TIME(HOUR(D6),MINUTE(D6)+3,SECOND(D6)) -> 0.2112037 | D6: =(IF(AND(D!$EY223<180),D!$FG223+(D!$EY223/15-12),0))/24 -> 0.20911567 | E6: =(IF(AND(D!$ER223<180),D!$FG223+(D!$ER223/15-12),0))/24 -> 0.14105524 | F6: =(IF(AND(D!$ET223<180),D!$FG223+(D!$ET223/15-12),0))/24 -> 0.11287904 | G6: =D!FG223/24 -> 0.50044907 | H6: =(K6+(D!FK223/2)) -> 0.46958887 | I6: =(IF(AND(D!$EW223<180),D!$FG223-(D!$EW223/15),0))/24 -> 0.30022617 | J6: =(IF(AND(D!$EY223<180),D!$FG223-(D!$EY223/15),0))/24 -> 0.29178248 | K6: =(IF(AND(D!$FC223<180),D!$FG223-(D!$FE223/15),0))/24 -> 0.23006208 | L6: =TIME(HOUR(K6),MINUTE(K6)-5,MINUTE(K6)) -> 0.22674769 | M6: 2 | N6: =(IF(AND(D!FZ223<180),D!GD223+(D!GB223/15-12),0))/24 -> 0.27941727 | O6: =(IF(AND(D!FX223<180),D!GD223+(D!FX223/15-12),0))/24 -> 0.25903708 | P6: =TIME(HOUR(Q6),MINUTE(Q6)+3,SECOND(Q6)) -> 0.22244213 | Q6: =(IF(AND(D!$FU223<180),D!$GD223+(D!$FU223/15-12),0))/24 -> 0.22035491 | R6: =(IF(AND(D!$FN223<180),D!$GD223+(D!$FN223/15-12),0))/24 -> 0.15193084 | S6: =(IF(AND(D!$FP223<180),D!$GD223+(D!$FP223/15-12),0))/24 -> 0.12122854 | T6: =D!GD223/24 -> 0.49640741 | U6: =(X6+(D!GG223/2)) -> 0.46687623 | V6: =(IF(AND(D!$FS223<180),D!$GD223-(D!$FS223/15),0))/24 -> 0.28037036 | W6: =(IF(AND(D!$FU223<180),D!$GD223-(D!$FU223/15),0))/24 -> 0.27245991 | X6: =(IF(AND(D!$FZ223<180),D!$GD223-(D!$GB223/15),0))/24 -> 0.21339755 | Y6: =TIME(HOUR(X6),MINUTE(X6)-5,MINUTE(X6)) -> 0.20980324 | Z6: 2 | AA6: =(IF(AND(D!FC181<180),D!FG181+(D!FE181/15-12),0))/24 -> 0.30400161 | AB6: =(IF(AND(D!FA181<180),D!FG181+(D!FA181/15-12),0))/24 -> 0.28371292 | AC6: =TIME(HOUR(AD6),MINUTE(AD6)+3,SECOND(AD6)) -> 0.24820602 | AD6: =(IF(AND(D!$EY181<180),D!$FG181+(D!$EY181/15-12),0))/24 -> 0.24612818 | AE6: =(IF(AND(D!$ER181<180),D!$FG181+(D!$ER181/15-12),0))/24 -> 0.17525177 | AF6: =(IF(AND(D!$ET181<180),D!$FG181+(D!$ET181/15-12),0))/24 -> 0.14026128 | AG6: =D!FG181/24 -> 0.50040741 | AH6: =(AK6+(D!FK181/2)) -> 0.4714707 | AI6: =(IF(AND(D!$EW181<180),D!$FG181-(D!$EW181/15),0))/24 -> 0.26222237 | AJ6: =(IF(AND(D!$EY181<180),D!$FG181-(D!$EY181/15),0))/24 -> 0.25468663 | AK6: =(IF(AND(D!$FC181<180),D!$FG181-(D!$FE181/15),0))/24 -> 0.19681321 | AL6: =TIME(HOUR(AK6),MINUTE(AK6)-10,MINUTE(AK6)) -> 0.19008102 | AM6: 2 | AN6: =(IF(AND(D!FZ181<180),D!GD181+(D!GB181/15-12),0))/24 -> 0.33559295 | AO6: =(IF(AND(D!FX181<180),D!GD181+(D!FX181/15-12),0))/24 -> 0.31402129 | AP6: =TIME(HOUR(AQ6),MINUTE(AQ6)+3,SECOND(AQ6)) -> 0.27736111 | AQ6: =(IF(AND(D!$FU181<180),D!$GD181+(D!$FU181/15-12),0))/24 -> 0.27527751 | AR6: =(IF(AND(D!$FN181<180),D!$GD181+(D!$FN181/15-12),0))/24 -> 0.19885866 | AS6: =(IF(AND(D!$FP181<180),D!$GD181+(D!$FP181/15-12),0))/24 -> 0.15819001 | AT6: =D!GD181/24 -> 0.50761574 | AU6: =(AX6+(D!GG181/2)) -> 0.47745802 | AV6: =(IF(AND(D!$FS181<180),D!$GD181-(D!$FS181/15),0))/24 -> 0.24756231 | AW6: =(IF(AND(D!$FU181<180),D!$GD181-(D!$FU181/15),0))/24 -> 0.23995397 | AX6: =(IF(AND(D!$FZ181<180),D!$GD181-(D!$GB181/15),0))/24 -> 0.17963853 | AY6: =TIME(HOUR(AX6),MINUTE(AX6)-10,MINUTE(AX6)) -> 0.17243056 | AZ6: 2 | BA6: =(IF(AND(D!FC139<180),D!FG139+(D!FE139/15-12),0))/24 -> 0.36659279 | BB6: =(IF(AND(D!FA139<180),D!FG139+(D!FA139/15-12),0))/24 -> 0.34214574 | BC6: =TIME(HOUR(BD6),MINUTE(BD6)+3,SECOND(BD6)) -> 0.30216435 | BD6: =(IF(AND(D!$EY139<180),D!$FG139+(D!$EY139/15-12),0))/24 -> 0.30008509 | BE6: =(IF(AND(D!$ER139<180),D!$FG139+(D!$ER139/15-12),0))/24 -> 0.21548102 | BF6: =(IF(AND(D!$ET139<180),D!$FG139+D!$ET139/15-12,0))/24 -> 0.1680757 | BG6: =D!FG139/24 -> 0.51224074 | BH6: =(BK6+(D!FK139/2)) -> 0.47898689 | BI6: =(IF(AND(D!$EW139<180),D!$FG139-(D!$EW139/15),0))/24 -> 0.23245855 | BJ6: =(IF(AND(D!$EY139<180),D!$FG139-(D!$EY139/15),0))/24 -> 0.22439639 | BK6: =(IF(AND(D!$FC139<180),D!$FG139-(D!$FE139/15),0))/24 -> 0.15788869 | BL6: =TIME(HOUR(BK6),MINUTE(BK6)-10,MINUTE(BK6)) -> 0.15123843 | BM6: 2 | BN6: =(IF(AND(D!FZ139<180),D!GD139+(D!GB139/15-12),0))/24 -> 0.3832798 | BO6: =(IF(AND(D!FX139<180),D!GD139+(D!FX139/15-12),0))/24 -> 0.35593839 | BP6: =TIME(HOUR(BQ6),MINUTE(BQ6)+3,SECOND(BQ6)) -> 0.31278935 | BQ6: =(IF(AND(D!$FU139<180),D!$GD139+(D!$FU139/15-12),0))/24 -> 0.31070024 | BR6: =(IF(AND(D!$FN139<180),D!$GD139+(D!$FN139/15-12),0))/24 -> 0.21977637 | BS6: =(IF(AND(D!$FP139<180),D!$GD139+(D!$FP139/15-12),0))/24 -> 0.16762455 | BT6: =D!GD139/24 -> 0.51074074 | BU6: =(BX6+(D!GG139/2)) -> 0.47445096 | BV6: =(IF(AND(D!$FS139<180),D!$GD139-(D!$FS139/15),0))/24 -> 0.21928821 | BW6: =(IF(AND(D!$FU139<180),D!$GD139-(D!$FU139/15),0))/24 -> 0.21078124 | BX6: =(IF(AND(D!$FZ139<180),D!$GD139-(D!$GB139/15),0))/24 -> 0.13820168 | BY6: =TIME(HOUR(BX6),MINUTE(BX6)-10,MINUTE(BX6)) -> 0.13146991 | BZ6: 2 | CA6: =(IF(AND(D!FC98<180),D!FG98+D!FE98/15-12,0))/24 -> 0.37619484 | CB6: =(IF(AND(D!FA98<180),D!FG98+D!FA98/15-12,0))/24 -> 0.34935728 | CC6: =TIME(HOUR(CD6),MINUTE(CD6)+3,SECOND(CD6)) -> 0.30673611 | CD6: =(IF(AND(D!$EY98<180),D!$FG98+(D!$EY98/15-12),0))/24 -> 0.30465321 | CE6: =(IF(AND(D!$ER98<180),D!$FG98+(D!$ER98/15-12),0))/24 -> 0.21473057 | CF6: =(IF(AND(D!$ET98<180),D!$FG98+(D!$ET98/15-12),0))/24 -> 0.16331413 | CG6: =D!FG98/24 -> 0.50649074 | CH6: =(CK6+(D!FK98/2)) -> 0.47071993 | CI6: =(IF(AND(D!$EW98<180),D!$FG98-(D!$EW98/15),0))/24 -> 0.21676119 | CJ6: =(IF(AND(D!$EY98<180),D!$FG98-(D!$EY98/15),0))/24 -> 0.20832827 | CK6: =(IF(AND(D!$FC98<180),D!$FG98-(D!$FE98/15),0))/24 -> 0.13678664 | CL6: =TIME(HOUR(CK6),MINUTE(CK6)-10,MINUTE(CK6)) -> 0.12935185 | CM6: 2 | CN6: =(IF(AND(D!FZ98<180),D!GD98+(D!GB98/15-12),0))/24 -> 0.3537267 | CO6: =(IF(AND(D!FX98<180),D!GD98+(D!FX98/15-12),0))/24 -> 0.33011248 | CP6: =TIME(HOUR(CQ6),MINUTE(CQ6)+3,SECOND(CQ6)) -> 0.29108796 | CQ6: =(IF(AND(D!$FU98<180),D!$GD98+(D!$FU98/15-12),0))/24 -> 0.28900886 | CR6: =(IF(AND(D!$FN98<180),D!$GD98+(D!$FN98/15-12),0))/24 -> 0.20652215 | CS6: =(IF(AND(D!$FP98<180),D!$GD98+(D!$FP98/15-12),0))/24 -> 0.16077553 | CT6: =D!GD98/24 -> 0.50574074 | CU6: =(CX6+(D!GG98/2)) -> 0.4793756 | CV6: =(IF(AND(D!$FS98<180),D!$GD98-(D!$FS98/15),0))/24 -> 0.23040015 | CW6: =(IF(AND(D!$FU98<180),D!$GD98-(D!$FU98/15),0))/24 -> 0.22247262 | CX6: =(IF(AND(D!$FZ98<180),D!$GD98-(D!$FZ98/15),0))/24 -> 0.16974235 | CY6: =TIME(HOUR(CX6),MINUTE(CX6)-10,MINUTE(CX6)) -> 0.1625463 | CZ6: 2 | DA6: =(IF(AND(D!FC52<180),D!FG52+(D!FC52/15-12),0))/24 -> 0.32150902 | DB6: =(IF(AND(D!FA52<180),D!FG52+(D!FA52/15-12),0))/24 -> 0.31101648 | DC6: =TIME(HOUR(DD6),MINUTE(DD6)+3,SECOND(DD6)) -> 0.27484954 | DD6: =(IF(AND(D!$EY52<180),D!$FG52+(D!$EY52/15-12),0))/24 -> 0.27276497 | DE6: =(IF(AND(D!$ER52<180),D!$FG52+(D!$ER52/15-12),0))/24 -> 0.1979634 | DF6: =(IF(AND(D!$ET52<180),D!$FG52+(D!$ET52/15-12),0))/24 -> 0.15878277 | DG6: =D!FG52/24 -> 0.51028241 | DH6: =(DK6+(D!FK52/2)) -> 0.48059618 | DI6: =(IF(AND(D!$EW52<180),D!$FG52-(D!$EW52/15),0))/24 -> 0.25535091 | DJ6: =(IF(AND(D!$EY52<180),D!$FG52-(D!$EY52/15),0))/24 -> 0.24779984 | DK6: =(IF(AND(D!$FC52<180),D!$FG52-(D!$FE52/15),0))/24 -> 0.1884274 | DL6: =TIME(HOUR(DK6),MINUTE(DK6)-10,MINUTE(DK6)) -> 0.1816088 | DM6: 2 | DN6: =(IF(AND(D!FZ52<180),D!GD52+D!GB52/15-12,0))/24 -> 0.31428089 | DO6: =(IF(AND(D!FX52<180),D!GD52+D!FX52/15-12,0))/24 -> 0.29325967 | DP6: =TIME(HOUR(DQ6),MINUTE(DQ6)+3,SECOND(DQ6)) -> 0.25766204 | DQ6: =(IF(AND(D!$EY52<180),D!GD52+(D!FU52/15-12),0))/24 -> 0.25557507 | DR6: =(IF(AND(D!$FN52<180),D!GD52+(D!FN52/15-12),0))/24 -> 0.18569506 | DS6: =(IF(AND(D!$FP52<180),D!GD52+(D!FP52/15-12),0))/24 -> 0.15206868 | DT6: =D!GD52/24 -> 0.51619907 | DU6: =(DX6+(D!GG52/2)) -> 0.48684616 | DV6: =(IF(AND(D!FS52<180),D!GD52-(D!FS52/15),0))/24 -> 0.28442167 | DW6: =(IF(AND(D!FU52<180),D!GD52-(D!FU52/15),0))/24 -> 0.27682308 | DX6: =(IF(AND(D!$FC52<180),D!GD52-(D!GB52/15),0))/24 -> 0.21811726 | DY6: =TIME(HOUR(DX6),MINUTE(DX6)-10,MINUTE(DX6)) -> 0.21127315 | DZ6: 2 | EA6: =(IF(AND(D!$FC7<180),D!$FG7+D!$FE7/15-12,0))/24 -> 0.2969183 | EB6: =(IF(AND(D!$FA7<180),D!$FG7+D!$FA7/15-12,0))/24 -> 0.27640491 | EC6: =TIME(HOUR(ED6),MINUTE(ED6)+3,SECOND(ED6)) -> 0.23938657 | ED6: =(IF(AND(D!$EY7<180),D!FG7+(D!EY7/15-12),0))/24 -> 0.23730661 | EE6: =(IF(AND(D!$ER7<180),D!FG7+(D!ER7/15-12),0))/24 -> 0.16906372 | EF6: =(IF(AND(D!$ET7<180),D!FG7+(D!ET7/15-12),0))/24 -> 0.13903615 | EG6: =D!FG7/24 -> 0.51728241 | EH6: =(EK6+(D!FK7/2)) -> 0.48747656 | EI6: =(IF(AND(D!EW7<180),D!FG7-(D!EW7/15),0))/24 -> 0.30528412 | EJ6: =(IF(AND(D!EY7<180),D!FG7-(D!EY7/15),0))/24 -> 0.29725821 | EK6: =(IF(AND(D!$FC7<180),D!$FG7-(D!$FE7/15),0))/24 -> 0.23764651 | EL6: =TIME(HOUR(EK6),MINUTE(EK6)-10,MINUTE(EK6)) -> 0.23104167 | EM6: 2 | EN6: =(IF(AND(D!FZ7<180),D!GD7+(D!GB7/15-12),0))/24 -> 0.27934009 | EO6: =(IF(AND(D!$FX7<180),D!$GD7+(D!$FX7/15-12),0))/24 -> 0.25814778 | EP6: =TIME(HOUR(EQ6),MINUTE(EQ6)+3,SECOND(EQ6)) -> 0.21924769 | EQ6: =(IF(AND(D!$FU7<180),D!$GD7+(D!$FU7/15-12),0))/24 -> 0.2171647 | ER6: =(IF(AND(D!$FN7<180),D!$GD7+(D!$FN7/15-12),0))/24 -> 0.14909166 | ES6: =(IF(AND(D!$FP7<180),D!$GD7+(D!$FP7/15-12),0))/24 -> 0.12123577 | ET6: =D!GD7/24 -> 0.51053241 | EU6: =(EX6+(D!GG7/2)) -> 0.47944471 | EV6: =(IF(AND(D!$FS7<180),D!$GD7-(D!$FS7/15),0))/24 -> 0.31243188 | EW6: =(IF(AND(D!$FU7<180),D!$GD7-(D!$FU7/15),0))/24 -> 0.30390012 | EX6: =(IF(AND(D!$FZ7<180),D!$GD7-(D!$GB7/15),0))/24 -> 0.24172472 | EY6: =TIME(HOUR(EX6),MINUTE(EX6)-5,MINUTE(EX6)) -> 0.23875 | EZ6: 2
A7: =(IF(AND(D!FC224<180),D!FG224+(D!FE224/15-12),0))/24 -> 0.27087677 | B7: =(IF(AND(D!FA224<180),D!FG224+(D!FA224/15-12),0))/24 -> 0.24978922 | C7: =TIME(HOUR(D7),MINUTE(D7)+3,SECOND(D7)) -> 0.21116898 | D7: =(IF(AND(D!$EY224<180),D!$FG224+(D!$EY224/15-12),0))/24 -> 0.20908601 | E7: =(IF(AND(D!$ER224<180),D!$FG224+(D!$ER224/15-12),0))/24 -> 0.14102439 | F7: =(IF(AND(D!$ET224<180),D!$FG224+(D!$ET224/15-12),0))/24 -> 0.11289895 | G7: =D!FG224/24 -> 0.50074074 | H7: =(K7+(D!FK224/2)) -> 0.46984536 | I7: =(IF(AND(D!$EW224<180),D!$FG224-(D!$EW224/15),0))/24 -> 0.3008528 | J7: =(IF(AND(D!$EY224<180),D!$FG224-(D!$EY224/15),0))/24 -> 0.29239548 | K7: =(IF(AND(D!$FC224<180),D!$FG224-(D!$FE224/15),0))/24 -> 0.23060471 | L7: =TIME(HOUR(K7),MINUTE(K7)-5,MINUTE(K7)) -> 0.2274537 | M7: 3 | N7: =(IF(AND(D!FZ224<180),D!GD224+(D!GB224/15-12),0))/24 -> 0.27886147 | O7: =(IF(AND(D!FX224<180),D!GD224+(D!FX224/15-12),0))/24 -> 0.2584618 | P7: =TIME(HOUR(Q7),MINUTE(Q7)+3,SECOND(Q7)) -> 0.22179398 | Q7: =(IF(AND(D!$FU224<180),D!$GD224+(D!$FU224/15-12),0))/24 -> 0.21971623 | R7: =(IF(AND(D!$FN224<180),D!$GD224+(D!$FN224/15-12),0))/24 -> 0.15132633 | S7: =(IF(AND(D!$FP224<180),D!$GD224+(D!$FP224/15-12),0))/24 -> 0.12073541 | T7: =D!GD224/24 -> 0.49640741 | U7: =(X7+(D!GG224/2)) -> 0.46683478 | V7: =(IF(AND(D!$FS224<180),D!$GD224-(D!$FS224/15),0))/24 -> 0.28102683 | W7: =(IF(AND(D!$FU224<180),D!$GD224-(D!$FU224/15),0))/24 -> 0.27309859 | X7: =(IF(AND(D!$FZ224<180),D!$GD224-(D!$GB224/15),0))/24 -> 0.21395334 | Y7: =TIME(HOUR(X7),MINUTE(X7)-5,MINUTE(X7)) -> 0.21050926 | Z7: 3 | AA7: =(IF(AND(D!FC182<180),D!FG182+(D!FE182/15-12),0))/24 -> 0.30300237 | AB7: =(IF(AND(D!FA182<180),D!FG182+(D!FA182/15-12),0))/24 -> 0.28273053 | AC7: =TIME(HOUR(AD7),MINUTE(AD7)+3,SECOND(AD7)) -> 0.24722222 | AD7: =(IF(AND(D!$EY182<180),D!$FG182+(D!$EY182/15-12),0))/24 -> 0.24514384 | AE7: =(IF(AND(D!$ER182<180),D!$FG182+(D!$ER182/15-12),0))/24 -> 0.17439577 | AF7: =(IF(AND(D!$ET182<180),D!$FG182+(D!$ET182/15-12),0))/24 -> 0.13956883 | AG7: =D!FG182/24 -> 0.50015741 | AH7: =(AK7+(D!FK182/2)) -> 0.47122814 | AI7: =(IF(AND(D!$EW182<180),D!$FG182-(D!$EW182/15),0))/24 -> 0.26271204 | AJ7: =(IF(AND(D!$EY182<180),D!$FG182-(D!$EY182/15),0))/24 -> 0.25517097 | AK7: =(IF(AND(D!$FC182<180),D!$FG182-(D!$FE182/15),0))/24 -> 0.19731244 | AL7: =TIME(HOUR(AK7),MINUTE(AK7)-10,MINUTE(AK7)) -> 0.19078704 | AM7: 3 | AN7: =(IF(AND(D!FZ182<180),D!GD182+(D!GB182/15-12),0))/24 -> 0.33448363 | AO7: =(IF(AND(D!FX182<180),D!GD182+(D!FX182/15-12),0))/24 -> 0.31298023 | AP7: =TIME(HOUR(AQ7),MINUTE(AQ7)+3,SECOND(AQ7)) -> 0.27640046 | AQ7: =(IF(AND(D!$FU182<180),D!$GD182+(D!$FU182/15-12),0))/24 -> 0.27431273 | AR7: =(IF(AND(D!$FN182<180),D!$GD182+(D!$FN182/15-12),0))/24 -> 0.19812877 | AS7: =(IF(AND(D!$FP182<180),D!$GD182+(D!$FP182/15-12),0))/24 -> 0.15767123 | AT7: =D!GD182/24 -> 0.50736574 | AU7: =(AX7+(D!GG182/2)) -> 0.47728029 | AV7: =(IF(AND(D!$FS182<180),D!$GD182-(D!$FS182/15),0))/24 -> 0.24801773 | AW7: =(IF(AND(D!$FU182<180),D!$GD182-(D!$FU182/15),0))/24 -> 0.24041875 | AX7: =(IF(AND(D!$FZ182<180),D!$GD182-(D!$GB182/15),0))/24 -> 0.18024785 | AY7: =TIME(HOUR(AX7),MINUTE(AX7)-10,MINUTE(AX7)) -> 0.17313657 | AZ7: 3 | BA7: =(IF(AND(D!FC140<180),D!FG140+(D!FE140/15-12),0))/24 -> 0.36571129 | BB7: =(IF(AND(D!FA140<180),D!FG140+(D!FA140/15-12),0))/24 -> 0.3413736 | BC7: =TIME(HOUR(BD7),MINUTE(BD7)+3,SECOND(BD7)) -> 0.3015162 | BD7: =(IF(AND(D!$EY140<180),D!$FG140+(D!$EY140/15-12),0))/24 -> 0.29943777 | BE7: =(IF(AND(D!$ER140<180),D!$FG140+(D!$ER140/15-12),0))/24 -> 0.21510279 | BF7: =(IF(AND(D!$ET140<180),D!$FG140+D!$ET140/15-12,0))/24 -> 0.16790599 | BG7: =D!FG140/24 -> 0.51215741 | BH7: =(BK7+(D!FK140/2)) -> 0.47902065 | BI7: =(IF(AND(D!$EW140<180),D!$FG140-(D!$EW140/15),0))/24 -> 0.23292163 | BJ7: =(IF(AND(D!$EY140<180),D!$FG140-(D!$EY140/15),0))/24 -> 0.22487705 | BK7: =(IF(AND(D!$FC140<180),D!$FG140-(D!$FE140/15),0))/24 -> 0.15860353 | BL7: =TIME(HOUR(BK7),MINUTE(BK7)-10,MINUTE(BK7)) -> 0.15194444 | BM7: 3 | BN7: =(IF(AND(D!FZ140<180),D!GD140+(D!GB140/15-12),0))/24 -> 0.38310265 | BO7: =(IF(AND(D!FX140<180),D!GD140+(D!FX140/15-12),0))/24 -> 0.3558159 | BP7: =TIME(HOUR(BQ7),MINUTE(BQ7)+3,SECOND(BQ7)) -> 0.31271991 | BQ7: =(IF(AND(D!$FU140<180),D!$GD140+(D!$FU140/15-12),0))/24 -> 0.3106353 | BR7: =(IF(AND(D!$FN140<180),D!$GD140+(D!$FN140/15-12),0))/24 -> 0.21981829 | BS7: =(IF(AND(D!$FP140<180),D!$GD140+(D!$FP140/15-12),0))/24 -> 0.16774469 | BT7: =D!GD140/24 -> 0.51086574 | BU7: =(BX7+(D!GG140/2)) -> 0.47463207 | BV7: =(IF(AND(D!$FS140<180),D!$GD140-(D!$FS140/15),0))/24 -> 0.21959519 | BW7: =(IF(AND(D!$FU140<180),D!$GD140-(D!$FU140/15),0))/24 -> 0.21109618 | BX7: =(IF(AND(D!$FZ140<180),D!$GD140-(D!$GB140/15),0))/24 -> 0.13862883 | BY7: =TIME(HOUR(BX7),MINUTE(BX7)-10,MINUTE(BX7)) -> 0.13146991 | BZ7: 3 | CA7: =(IF(AND(D!FC99<180),D!FG99+D!FE99/15-12,0))/24 -> 0.37677106 | CB7: =(IF(AND(D!FA99<180),D!FG99+D!FA99/15-12,0))/24 -> 0.34985467 | CC7: =TIME(HOUR(CD7),MINUTE(CD7)+3,SECOND(CD7)) -> 0.30715278 | CD7: =(IF(AND(D!$EY99<180),D!$FG99+(D!$EY99/15-12),0))/24 -> 0.30506647 | CE7: =(IF(AND(D!$ER99<180),D!$FG99+(D!$ER99/15-12),0))/24 -> 0.21498469 | CF7: =(IF(AND(D!$ET99<180),D!$FG99+(D!$ET99/15-12),0))/24 -> 0.163451 | CG7: =D!FG99/24 -> 0.50661574 | CH7: =(CK7+(D!FK99/2)) -> 0.47076344 | CI7: =(IF(AND(D!$EW99<180),D!$FG99-(D!$EW99/15),0))/24 -> 0.21660962 | CJ7: =(IF(AND(D!$EY99<180),D!$FG99-(D!$EY99/15),0))/24 -> 0.20816501 | CK7: =(IF(AND(D!$FC99<180),D!$FG99-(D!$FE99/15),0))/24 -> 0.13646042 | CL7: =TIME(HOUR(CK7),MINUTE(CK7)-10,MINUTE(CK7)) -> 0.12935185 | CM7: 3 | CN7: =(IF(AND(D!FZ99<180),D!GD99+(D!GB99/15-12),0))/24 -> 0.35449304 | CO7: =(IF(AND(D!FX99<180),D!GD99+(D!FX99/15-12),0))/24 -> 0.33077284 | CP7: =TIME(HOUR(CQ7),MINUTE(CQ7)+3,SECOND(CQ7)) -> 0.29163194 | CQ7: =(IF(AND(D!$FU99<180),D!$GD99+(D!$FU99/15-12),0))/24 -> 0.28954669 | CR7: =(IF(AND(D!$FN99<180),D!$GD99+(D!$FN99/15-12),0))/24 -> 0.20678146 | CS7: =(IF(AND(D!$FP99<180),D!$GD99+(D!$FP99/15-12),0))/24 -> 0.16081415 | CT7: =D!GD99/24 -> 0.50565741 | CU7: =(CX7+(D!GG99/2)) -> 0.47920702 | CV7: =(IF(AND(D!$FS99<180),D!$GD99-(D!$FS99/15),0))/24 -> 0.22971284 | CW7: =(IF(AND(D!$FU99<180),D!$GD99-(D!$FU99/15),0))/24 -> 0.22176812 | CX7: =(IF(AND(D!$FZ99<180),D!$GD99-(D!$FZ99/15),0))/24 -> 0.16886734 | CY7: =TIME(HOUR(CX7),MINUTE(CX7)-10,MINUTE(CX7)) -> 0.16184028 | CZ7: 3 | DA7: =(IF(AND(D!FC53<180),D!FG53+(D!FC53/15-12),0))/24 -> 0.32212501 | DB7: =(IF(AND(D!FA53<180),D!FG53+(D!FA53/15-12),0))/24 -> 0.31160617 | DC7: =TIME(HOUR(DD7),MINUTE(DD7)+3,SECOND(DD7)) -> 0.27538194 | DD7: =(IF(AND(D!$EY53<180),D!$FG53+(D!$EY53/15-12),0))/24 -> 0.27329315 | DE7: =(IF(AND(D!$ER53<180),D!$FG53+(D!$ER53/15-12),0))/24 -> 0.19827354 | DF7: =(IF(AND(D!$ET53<180),D!$FG53+(D!$ET53/15-12),0))/24 -> 0.15888716 | DG7: =D!FG53/24 -> 0.51007407 | DH7: =(DK7+(D!FK53/2)) -> 0.48032809 | DI7: =(IF(AND(D!$EW53<180),D!$FG53-(D!$EW53/15),0))/24 -> 0.25441271 | DJ7: =(IF(AND(D!$EY53<180),D!$FG53-(D!$EY53/15),0))/24 -> 0.246855 | DK7: =(IF(AND(D!$FC53<180),D!$FG53-(D!$FE53/15),0))/24 -> 0.18736303 | DL7: =TIME(HOUR(DK7),MINUTE(DK7)-10,MINUTE(DK7)) -> 0.18019676 | DM7: 3 | DN7: =(IF(AND(D!FZ53<180),D!GD53+D!GB53/15-12,0))/24 -> 0.31482149 | DO7: =(IF(AND(D!FX53<180),D!GD53+D!FX53/15-12,0))/24 -> 0.29380783 | DP7: =TIME(HOUR(DQ7),MINUTE(DQ7)+3,SECOND(DQ7)) -> 0.25822917 | DQ7: =(IF(AND(D!$EY53<180),D!GD53+(D!FU53/15-12),0))/24 -> 0.25614436 | DR7: =(IF(AND(D!$FN53<180),D!GD53+(D!FN53/15-12),0))/24 -> 0.18616159 | DS7: =(IF(AND(D!$FP53<180),D!GD53+(D!FP53/15-12),0))/24 -> 0.15238246 | DT7: =D!GD53/24 -> 0.51603241 | DU7: =(DX7+(D!GG53/2)) -> 0.48669384 | DV7: =(IF(AND(D!FS53<180),D!GD53-(D!FS53/15),0))/24 -> 0.2835098 | DW7: =(IF(AND(D!FU53<180),D!GD53-(D!FU53/15),0))/24 -> 0.27592045 | DX7: =(IF(AND(D!$FC53<180),D!GD53-(D!GB53/15),0))/24 -> 0.21724332 | DY7: =TIME(HOUR(DX7),MINUTE(DX7)-10,MINUTE(DX7)) -> 0.20986111 | DZ7: 3 | EA7: =(IF(AND(D!$FC8<180),D!$FG8+D!$FE8/15-12,0))/24 -> 0.29751918 | EB7: =(IF(AND(D!$FA8<180),D!$FG8+D!$FA8/15-12,0))/24 -> 0.27702855 | EC7: =TIME(HOUR(ED7),MINUTE(ED7)+3,SECOND(ED7)) -> 0.24008102 | ED7: =(IF(AND(D!$EY8<180),D!FG8+(D!EY8/15-12),0))/24 -> 0.23799902 | EE7: =(IF(AND(D!$ER8<180),D!FG8+(D!ER8/15-12),0))/24 -> 0.1697324 | EF7: =(IF(AND(D!$ET8<180),D!FG8+(D!ET8/15-12),0))/24 -> 0.13960151 | EG7: =D!FG8/24 -> 0.51736574 | EH7: =(EK7+(D!FK8/2)) -> 0.48760566 | EI7: =(IF(AND(D!EW8<180),D!FG8-(D!EW8/15),0))/24 -> 0.30473949 | EJ7: =(IF(AND(D!EY8<180),D!FG8-(D!EY8/15),0))/24 -> 0.29673247 | EK7: =(IF(AND(D!$FC8<180),D!$FG8-(D!$FE8/15),0))/24 -> 0.2372123 | EL7: =TIME(HOUR(EK7),MINUTE(EK7)-10,MINUTE(EK7)) -> 0.23033565 | EM7: 3 | EN7: =(IF(AND(D!FZ8<180),D!GD8+(D!GB8/15-12),0))/24 -> 0.27984157 | EO7: =(IF(AND(D!$FX8<180),D!$GD8+(D!$FX8/15-12),0))/24 -> 0.25866286 | EP7: =TIME(HOUR(EQ7),MINUTE(EQ7)+3,SECOND(EQ7)) -> 0.21980324 | EQ7: =(IF(AND(D!$FU8<180),D!$GD8+(D!$FU8/15-12),0))/24 -> 0.217716 | ER7: =(IF(AND(D!$FN8<180),D!$GD8+(D!$FN8/15-12),0))/24 -> 0.14964489 | ES7: =(IF(AND(D!$FP8<180),D!$GD8+(D!$FP8/15-12),0))/24 -> 0.12175478 | ET7: =D!GD8/24 -> 0.51086574 | EU7: =(EX7+(D!GG8/2)) -> 0.47980296 | EV7: =(IF(AND(D!$FS8<180),D!$GD8-(D!$FS8/15),0))/24 -> 0.31253761 | EW7: =(IF(AND(D!$FU8<180),D!$GD8-(D!$FU8/15),0))/24 -> 0.30401548 | EX7: =(IF(AND(D!$FZ8<180),D!$GD8-(D!$GB8/15),0))/24 -> 0.24188991 | EY7: =TIME(HOUR(EX7),MINUTE(EX7)-5,MINUTE(EX7)) -> 0.23875 | EZ7: 3
A8: =(IF(AND(D!FC225<180),D!FG225+(D!FE225/15-12),0))/24 -> 0.27088812 | B8: =(IF(AND(D!FA225<180),D!FG225+(D!FA225/15-12),0))/24 -> 0.24978221 | C8: =TIME(HOUR(D8),MINUTE(D8)+3,SECOND(D8)) -> 0.21111111 | D8: =(IF(AND(D!$EY225<180),D!$FG225+(D!$EY225/15-12),0))/24 -> 0.20902978 | E8: =(IF(AND(D!$ER225<180),D!$FG225+(D!$ER225/15-12),0))/24 -> 0.14096673 | F8: =(IF(AND(D!$ET225<180),D!$FG225+(D!$ET225/15-12),0))/24 -> 0.11288961 | G8: =D!FG225/24 -> 0.50099074 | H8: =(K8+(D!FK225/2)) -> 0.47006157 | I8: =(IF(AND(D!$EW225<180),D!$FG225-(D!$EW225/15),0))/24 -> 0.30142213 | J8: =(IF(AND(D!$EY225<180),D!$FG225-(D!$EY225/15),0))/24 -> 0.29295171 | K8: =(IF(AND(D!$FC225<180),D!$FG225-(D!$FE225/15),0))/24 -> 0.23109336 | L8: =TIME(HOUR(K8),MINUTE(K8)-5,MINUTE(K8)) -> 0.2274537 | M8: 4 | N8: =(IF(AND(D!FZ225<180),D!GD225+(D!GB225/15-12),0))/24 -> 0.27831165 | O8: =(IF(AND(D!FX225<180),D!GD225+(D!FX225/15-12),0))/24 -> 0.25789174 | P8: =TIME(HOUR(Q8),MINUTE(Q8)+3,SECOND(Q8)) -> 0.22116898 | Q8: =(IF(AND(D!$FU225<180),D!$GD225+(D!$FU225/15-12),0))/24 -> 0.21908148 | R8: =(IF(AND(D!$FN225<180),D!$GD225+(D!$FN225/15-12),0))/24 -> 0.1507237 | S8: =(IF(AND(D!$FP225<180),D!$GD225+(D!$FP225/15-12),0))/24 -> 0.12024287 | T8: =D!GD225/24 -> 0.49640741 | U8: =(X8+(D!GG225/2)) -> 0.46679233 | V8: =(IF(AND(D!$FS225<180),D!$GD225-(D!$FS225/15),0))/24 -> 0.28167965 | W8: =(IF(AND(D!$FU225<180),D!$GD225-(D!$FU225/15),0))/24 -> 0.27373333 | X8: =(IF(AND(D!$FZ225<180),D!$GD225-(D!$GB225/15),0))/24 -> 0.21450317 | Y8: =TIME(HOUR(X8),MINUTE(X8)-5,MINUTE(X8)) -> 0.21050926 | Z8: 4 | AA8: =(IF(AND(D!FC183<180),D!FG183+(D!FE183/15-12),0))/24 -> 0.30205008 | AB8: =(IF(AND(D!FA183<180),D!FG183+(D!FA183/15-12),0))/24 -> 0.28179354 | AC8: =TIME(HOUR(AD8),MINUTE(AD8)+3,SECOND(AD8)) -> 0.24628472 | AD8: =(IF(AND(D!$EY183<180),D!$FG183+(D!$EY183/15-12),0))/24 -> 0.24420238 | AE8: =(IF(AND(D!$ER183<180),D!$FG183+(D!$ER183/15-12),0))/24 -> 0.17357899 | AF8: =(IF(AND(D!$ET183<180),D!$FG183+(D!$ET183/15-12),0))/24 -> 0.13891379 | AG8: =D!FG183/24 -> 0.49994907 | AH8: =(AK8+(D!FK183/2)) -> 0.47102522 | AI8: =(IF(AND(D!$EW183<180),D!$FG183-(D!$EW183/15),0))/24 -> 0.26324267 | AJ8: =(IF(AND(D!$EY183<180),D!$FG183-(D!$EY183/15),0))/24 -> 0.25569577 | AK8: =(IF(AND(D!$FC183<180),D!$FG183-(D!$FE183/15),0))/24 -> 0.19784807 | AL8: =TIME(HOUR(AK8),MINUTE(AK8)-10,MINUTE(AK8)) -> 0.19078704 | AM8: 4 | AN8: =(IF(AND(D!FZ183<180),D!GD183+(D!GB183/15-12),0))/24 -> 0.33342029 | AO8: =(IF(AND(D!FX183<180),D!GD183+(D!FX183/15-12),0))/24 -> 0.3119832 | AP8: =TIME(HOUR(AQ8),MINUTE(AQ8)+3,SECOND(AQ8)) -> 0.27547454 | AQ8: =(IF(AND(D!$FU183<180),D!$GD183+(D!$FU183/15-12),0))/24 -> 0.27338931 | AR8: =(IF(AND(D!$FN183<180),D!$GD183+(D!$FN183/15-12),0))/24 -> 0.19743659 | AS8: =(IF(AND(D!$FP183<180),D!$GD183+(D!$FP183/15-12),0))/24 -> 0.1571884 | AT8: =D!GD183/24 -> 0.50715741 | AU8: =(AX8+(D!GG183/2)) -> 0.47714192 | AV8: =(IF(AND(D!$FS183<180),D!$GD183-(D!$FS183/15),0))/24 -> 0.24851558 | AW8: =(IF(AND(D!$FU183<180),D!$GD183-(D!$FU183/15),0))/24 -> 0.2409255 | AX8: =(IF(AND(D!$FZ183<180),D!$GD183-(D!$GB183/15),0))/24 -> 0.18089452 | AY8: =TIME(HOUR(AX8),MINUTE(AX8)-10,MINUTE(AX8)) -> 0.17384259 | AZ8: 4 | BA8: =(IF(AND(D!FC141<180),D!FG141+(D!FE141/15-12),0))/24 -> 0.36486327 | BB8: =(IF(AND(D!FA141<180),D!FG141+(D!FA141/15-12),0))/24 -> 0.34063462 | BC8: =TIME(HOUR(BD8),MINUTE(BD8)+3,SECOND(BD8)) -> 0.30090278 | BD8: =(IF(AND(D!$EY141<180),D!$FG141+(D!$EY141/15-12),0))/24 -> 0.29882351 | BE8: =(IF(AND(D!$ER141<180),D!$FG141+(D!$ER141/15-12),0))/24 -> 0.2147594 | BF8: =(IF(AND(D!$ET141<180),D!$FG141+D!$ET141/15-12,0))/24 -> 0.16777312 | BG8: =D!FG141/24 -> 0.51211574 | BH8: =(BK8+(D!FK141/2)) -> 0.47909586 | BI8: =(IF(AND(D!$EW141<180),D!$FG141-(D!$EW141/15),0))/24 -> 0.23343498 | BJ8: =(IF(AND(D!$EY141<180),D!$FG141-(D!$EY141/15),0))/24 -> 0.22540798 | BK8: =(IF(AND(D!$FC141<180),D!$FG141-(D!$FE141/15),0))/24 -> 0.15936821 | BL8: =TIME(HOUR(BK8),MINUTE(BK8)-10,MINUTE(BK8)) -> 0.15265046 | BM8: 4 | BN8: =(IF(AND(D!FZ141<180),D!GD141+(D!GB141/15-12),0))/24 -> 0.38290028 | BO8: =(IF(AND(D!FX141<180),D!GD141+(D!FX141/15-12),0))/24 -> 0.35567251 | BP8: =TIME(HOUR(BQ8),MINUTE(BQ8)+3,SECOND(BQ8)) -> 0.31263889 | BQ8: =(IF(AND(D!$FU141<180),D!$GD141+(D!$FU141/15-12),0))/24 -> 0.31055408 | BR8: =(IF(AND(D!$FN141<180),D!$GD141+(D!$FN141/15-12),0))/24 -> 0.2198528 | BS8: =(IF(AND(D!$FP141<180),D!$GD141+(D!$FP141/15-12),0))/24 -> 0.167864 | BT8: =D!GD141/24 -> 0.51099074 | BU8: =(BX8+(D!GG141/2)) -> 0.47481764 | BV8: =(IF(AND(D!$FS141<180),D!$GD141-(D!$FS141/15),0))/24 -> 0.2199178 | BW8: =(IF(AND(D!$FU141<180),D!$GD141-(D!$FU141/15),0))/24 -> 0.2114274 | BX8: =(IF(AND(D!$FZ141<180),D!$GD141-(D!$GB141/15),0))/24 -> 0.1390812 | BY8: =TIME(HOUR(BX8),MINUTE(BX8)-10,MINUTE(BX8)) -> 0.13217593 | BZ8: 4 | CA8: =(IF(AND(D!FC100<180),D!FG100+D!FE100/15-12,0))/24 -> 0.37732752 | CB8: =(IF(AND(D!FA100<180),D!FG100+D!FA100/15-12,0))/24 -> 0.35033526 | CC8: =TIME(HOUR(CD8),MINUTE(CD8)+3,SECOND(CD8)) -> 0.3075463 | CD8: =(IF(AND(D!$EY100<180),D!$FG100+(D!$EY100/15-12),0))/24 -> 0.30546631 | CE8: =(IF(AND(D!$ER100<180),D!$FG100+(D!$ER100/15-12),0))/24 -> 0.21523227 | CF8: =(IF(AND(D!$ET100<180),D!$FG100+(D!$ET100/15-12),0))/24 -> 0.16358654 | CG8: =D!FG100/24 -> 0.50674074 | CH8: =(CK8+(D!FK100/2)) -> 0.47081014 | CI8: =(IF(AND(D!$EW100<180),D!$FG100-(D!$EW100/15),0))/24 -> 0.21647099 | CJ8: =(IF(AND(D!$EY100<180),D!$FG100-(D!$EY100/15),0))/24 -> 0.20801517 | CK8: =(IF(AND(D!$FC100<180),D!$FG100-(D!$FE100/15),0))/24 -> 0.13615396 | CL8: =TIME(HOUR(CK8),MINUTE(CK8)-10,MINUTE(CK8)) -> 0.12935185 | CM8: 4 | CN8: =(IF(AND(D!FZ100<180),D!GD100+(D!GB100/15-12),0))/24 -> 0.35529422 | CO8: =(IF(AND(D!FX100<180),D!GD100+(D!FX100/15-12),0))/24 -> 0.33146734 | CP8: =TIME(HOUR(CQ8),MINUTE(CQ8)+3,SECOND(CQ8)) -> 0.29219907 | CQ8: =(IF(AND(D!$FU100<180),D!$GD100+(D!$FU100/15-12),0))/24 -> 0.29011802 | CR8: =(IF(AND(D!$FN100<180),D!$GD100+(D!$FN100/15-12),0))/24 -> 0.20707518 | CS8: =(IF(AND(D!$FP100<180),D!$GD100+(D!$FP100/15-12),0))/24 -> 0.16088871 | CT8: =D!GD100/24 -> 0.50561574 | CU8: =(CX8+(D!GG100/2)) -> 0.47907964 | CV8: =(IF(AND(D!$FS100<180),D!$GD100-(D!$FS100/15),0))/24 -> 0.22907549 | CW8: =(IF(AND(D!$FU100<180),D!$GD100-(D!$FU100/15),0))/24 -> 0.22111346 | CX8: =(IF(AND(D!$FZ100<180),D!$GD100-(D!$FZ100/15),0))/24 -> 0.16804125 | CY8: =TIME(HOUR(CX8),MINUTE(CX8)-10,MINUTE(CX8)) -> 0.16042824 | CZ8: 4 | DA8: =(IF(AND(D!FC54<180),D!FG54+(D!FC54/15-12),0))/24 -> 0.32274406 | DB8: =(IF(AND(D!FA54<180),D!FG54+(D!FA54/15-12),0))/24 -> 0.31219803 | DC8: =TIME(HOUR(DD8),MINUTE(DD8)+3,SECOND(DD8)) -> 0.27590278 | DD8: =(IF(AND(D!$EY54<180),D!$FG54+(D!$EY54/15-12),0))/24 -> 0.27382075 | DE8: =(IF(AND(D!$ER54<180),D!$FG54+(D!$ER54/15-12),0))/24 -> 0.19857934 | DF8: =(IF(AND(D!$ET54<180),D!$FG54+(D!$ET54/15-12),0))/24 -> 0.15898544 | DG8: =D!FG54/24 -> 0.50986574 | DH8: =(DK8+(D!FK54/2)) -> 0.48005765 | DI8: =(IF(AND(D!$EW54<180),D!$FG54-(D!$EW54/15),0))/24 -> 0.25347558 | DJ8: =(IF(AND(D!$EY54<180),D!$FG54-(D!$EY54/15),0))/24 -> 0.24591073 | DK8: =(IF(AND(D!$FC54<180),D!$FG54-(D!$FE54/15),0))/24 -> 0.18629456 | DL8: =TIME(HOUR(DK8),MINUTE(DK8)-10,MINUTE(DK8)) -> 0.17949074 | DM8: 4 | DN8: =(IF(AND(D!FZ54<180),D!GD54+D!GB54/15-12,0))/24 -> 0.31540883 | DO8: =(IF(AND(D!FX54<180),D!GD54+D!FX54/15-12,0))/24 -> 0.29440269 | DP8: =TIME(HOUR(DQ8),MINUTE(DQ8)+3,SECOND(DQ8)) -> 0.25884259 | DQ8: =(IF(AND(D!$EY54<180),D!GD54+(D!FU54/15-12),0))/24 -> 0.25675793 | DR8: =(IF(AND(D!$FN54<180),D!GD54+(D!FN54/15-12),0))/24 -> 0.1866687 | DS8: =(IF(AND(D!$FP54<180),D!GD54+(D!FP54/15-12),0))/24 -> 0.1527349 | DT8: =D!GD54/24 -> 0.51590741 | DU8: =(DX8+(D!GG54/2)) -> 0.48658196 | DV8: =(IF(AND(D!FS54<180),D!GD54-(D!FS54/15),0))/24 -> 0.28263748 | DW8: =(IF(AND(D!FU54<180),D!GD54-(D!FU54/15),0))/24 -> 0.27505689 | DX8: =(IF(AND(D!$FC54<180),D!GD54-(D!GB54/15),0))/24 -> 0.21640599 | DY8: =TIME(HOUR(DX8),MINUTE(DX8)-10,MINUTE(DX8)) -> 0.20915509 | DZ8: 4 | EA8: =(IF(AND(D!$FC9<180),D!$FG9+D!$FE9/15-12,0))/24 -> 0.29808945 | EB8: =(IF(AND(D!$FA9<180),D!$FG9+D!$FA9/15-12,0))/24 -> 0.27762119 | EC8: =TIME(HOUR(ED8),MINUTE(ED8)+3,SECOND(ED8)) -> 0.24074074 | ED8: =(IF(AND(D!$EY9<180),D!FG9+(D!EY9/15-12),0))/24 -> 0.23866002 | EE8: =(IF(AND(D!$ER9<180),D!FG9+(D!ER9/15-12),0))/24 -> 0.17036765 | EF8: =(IF(AND(D!$ET9<180),D!FG9+(D!ET9/15-12),0))/24 -> 0.14013119 | EG8: =D!FG9/24 -> 0.51740741 | EH8: =(EK8+(D!FK9/2)) -> 0.48769269 | EI8: =(IF(AND(D!EW9<180),D!FG9-(D!EW9/15),0))/24 -> 0.30414298 | EJ8: =(IF(AND(D!EY9<180),D!FG9-(D!EY9/15),0))/24 -> 0.2961548 | EK8: =(IF(AND(D!$FC9<180),D!$FG9-(D!$FE9/15),0))/24 -> 0.23672536 | EL8: =TIME(HOUR(EK8),MINUTE(EK8)-10,MINUTE(EK8)) -> 0.22962963 | EM8: 4 | EN8: =(IF(AND(D!FZ9<180),D!GD9+(D!GB9/15-12),0))/24 -> 0.2803155 | EO8: =(IF(AND(D!$FX9<180),D!$GD9+(D!$FX9/15-12),0))/24 -> 0.25915143 | EP8: =TIME(HOUR(EQ8),MINUTE(EQ8)+3,SECOND(EQ8)) -> 0.22032407 | EQ8: =(IF(AND(D!$FU9<180),D!$GD9+(D!$FU9/15-12),0))/24 -> 0.21824357 | ER8: =(IF(AND(D!$FN9<180),D!$GD9+(D!$FN9/15-12),0))/24 -> 0.15017438 | ES8: =(IF(AND(D!$FP9<180),D!$GD9+(D!$FP9/15-12),0))/24 -> 0.12224723 | ET8: =D!GD9/24 -> 0.51115741 | EU8: =(EX8+(D!GG9/2)) -> 0.48012145 | EV8: =(IF(AND(D!$FS9<180),D!$GD9-(D!$FS9/15),0))/24 -> 0.312583 | EW8: =(IF(AND(D!$FU9<180),D!$GD9-(D!$FU9/15),0))/24 -> 0.30407124 | EX8: =(IF(AND(D!$FZ9<180),D!$GD9-(D!$GB9/15),0))/24 -> 0.24199932 | EY8: =TIME(HOUR(EX8),MINUTE(EX8)-5,MINUTE(EX8)) -> 0.23875 | EZ8: 4
A9: =(IF(AND(D!FC226<180),D!FG226+(D!FE226/15-12),0))/24 -> 0.27095346 | B9: =(IF(AND(D!FA226<180),D!FG226+(D!FA226/15-12),0))/24 -> 0.24982995 | C9: =TIME(HOUR(D9),MINUTE(D9)+3,SECOND(D9)) -> 0.21111111 | D9: =(IF(AND(D!$EY226<180),D!$FG226+(D!$EY226/15-12),0))/24 -> 0.20903041 | E9: =(IF(AND(D!$ER226<180),D!$FG226+(D!$ER226/15-12),0))/24 -> 0.14096577 | F9: =(IF(AND(D!$ET226<180),D!$FG226+(D!$ET226/15-12),0))/24 -> 0.11293451 | G9: =D!FG226/24 -> 0.50128241 | H9: =(K9+(D!FK226/2)) -> 0.47032088 | I9: =(IF(AND(D!$EW226<180),D!$FG226-(D!$EW226/15),0))/24 -> 0.30201736 | J9: =(IF(AND(D!$EY226<180),D!$FG226-(D!$EY226/15),0))/24 -> 0.2935344 | K9: =(IF(AND(D!$FC226<180),D!$FG226-(D!$FE226/15),0))/24 -> 0.23161135 | L9: =TIME(HOUR(K9),MINUTE(K9)-5,MINUTE(K9)) -> 0.22815972 | M9: 5 | N9: =(IF(AND(D!FZ226<180),D!GD226+(D!GB226/15-12),0))/24 -> 0.27777128 | O9: =(IF(AND(D!FX226<180),D!GD226+(D!FX226/15-12),0))/24 -> 0.25733057 | P9: =TIME(HOUR(Q9),MINUTE(Q9)+3,SECOND(Q9)) -> 0.22053241 | Q9: =(IF(AND(D!$FU226<180),D!$GD226+(D!$FU226/15-12),0))/24 -> 0.21845481 | R9: =(IF(AND(D!$FN226<180),D!$GD226+(D!$FN226/15-12),0))/24 -> 0.15012697 | S9: =(IF(AND(D!$FP226<180),D!$GD226+(D!$FP226/15-12),0))/24 -> 0.11975423 | T9: =D!GD226/24 -> 0.49640741 | U9: =(X9+(D!GG226/2)) -> 0.46674917 | V9: =(IF(AND(D!$FS226<180),D!$GD226-(D!$FS226/15),0))/24 -> 0.28232454 | W9: =(IF(AND(D!$FU226<180),D!$GD226-(D!$FU226/15),0))/24 -> 0.27436 | X9: =(IF(AND(D!$FZ226<180),D!$GD226-(D!$GB226/15),0))/24 -> 0.21504354 | Y9: =TIME(HOUR(X9),MINUTE(X9)-5,MINUTE(X9)) -> 0.21121528 | Z9: 5 | AA9: =(IF(AND(D!FC184<180),D!FG184+(D!FE184/15-12),0))/24 -> 0.30110103 | AB9: =(IF(AND(D!FA184<180),D!FG184+(D!FA184/15-12),0))/24 -> 0.28085831 | AC9: =TIME(HOUR(AD9),MINUTE(AD9)+3,SECOND(AD9)) -> 0.24534722 | AD9: =(IF(AND(D!$EY184<180),D!$FG184+(D!$EY184/15-12),0))/24 -> 0.24326015 | AE9: =(IF(AND(D!$ER184<180),D!$FG184+(D!$ER184/15-12),0))/24 -> 0.17275812 | AF9: =(IF(AND(D!$ET184<180),D!$FG184+(D!$ET184/15-12),0))/24 -> 0.13825333 | AG9: =D!FG184/24 -> 0.49974074 | AH9: =(AK9+(D!FK184/2)) -> 0.4708203 | AI9: =(IF(AND(D!$EW184<180),D!$FG184-(D!$EW184/15),0))/24 -> 0.26377458 | AJ9: =(IF(AND(D!$EY184<180),D!$FG184-(D!$EY184/15),0))/24 -> 0.25622133 | AK9: =(IF(AND(D!$FC184<180),D!$FG184-(D!$FE184/15),0))/24 -> 0.19838045 | AL9: =TIME(HOUR(AK9),MINUTE(AK9)-10,MINUTE(AK9)) -> 0.19149306 | AM9: 5 | AN9: =(IF(AND(D!FZ184<180),D!GD184+(D!GB184/15-12),0))/24 -> 0.3323172 | AO9: =(IF(AND(D!FX184<180),D!GD184+(D!FX184/15-12),0))/24 -> 0.31094466 | AP9: =TIME(HOUR(AQ9),MINUTE(AQ9)+3,SECOND(AQ9)) -> 0.27450231 | AQ9: =(IF(AND(D!$FU184<180),D!$GD184+(D!$FU184/15-12),0))/24 -> 0.27242193 | AR9: =(IF(AND(D!$FN184<180),D!$GD184+(D!$FN184/15-12),0))/24 -> 0.19669742 | AS9: =(IF(AND(D!$FP184<180),D!$GD184+(D!$FP184/15-12),0))/24 -> 0.15665738 | AT9: =D!GD184/24 -> 0.50690741 | AU9: =(AX9+(D!GG184/2)) -> 0.47695977 | AV9: =(IF(AND(D!$FS184<180),D!$GD184-(D!$FS184/15),0))/24 -> 0.2489745 | AW9: =(IF(AND(D!$FU184<180),D!$GD184-(D!$FU184/15),0))/24 -> 0.24139288 | AX9: =(IF(AND(D!$FZ184<180),D!$GD184-(D!$GB184/15),0))/24 -> 0.18149761 | AY9: =TIME(HOUR(AX9),MINUTE(AX9)-10,MINUTE(AX9)) -> 0.17454861 | AZ9: 5 | BA9: =(IF(AND(D!FC142<180),D!FG142+(D!FE142/15-12),0))/24 -> 0.36396865 | BB9: =(IF(AND(D!FA142<180),D!FG142+(D!FA142/15-12),0))/24 -> 0.33984823 | BC9: =TIME(HOUR(BD9),MINUTE(BD9)+3,SECOND(BD9)) -> 0.30024306 | BD9: =(IF(AND(D!$EY142<180),D!$FG142+(D!$EY142/15-12),0))/24 -> 0.2981612 | BE9: =(IF(AND(D!$ER142<180),D!$FG142+(D!$ER142/15-12),0))/24 -> 0.21436859 | BF9: =(IF(AND(D!$ET142<180),D!$FG142+D!$ET142/15-12,0))/24 -> 0.16759397 | BG9: =D!FG142/24 -> 0.51203241 | BH9: =(BK9+(D!FK142/2)) -> 0.47912868 | BI9: =(IF(AND(D!$EW142<180),D!$FG142-(D!$EW142/15),0))/24 -> 0.23391315 | BJ9: =(IF(AND(D!$EY142<180),D!$FG142-(D!$EY142/15),0))/24 -> 0.22590362 | BK9: =(IF(AND(D!$FC142<180),D!$FG142-(D!$FE142/15),0))/24 -> 0.16009616 | BL9: =TIME(HOUR(BK9),MINUTE(BK9)-10,MINUTE(BK9)) -> 0.15335648 | BM9: 5 | BN9: =(IF(AND(D!FZ142<180),D!GD142+(D!GB142/15-12),0))/24 -> 0.382673 | BO9: =(IF(AND(D!FX142<180),D!GD142+(D!FX142/15-12),0))/24 -> 0.35550839 | BP9: =TIME(HOUR(BQ9),MINUTE(BQ9)+3,SECOND(BQ9)) -> 0.31253472 | BQ9: =(IF(AND(D!$FU142<180),D!$GD142+(D!$FU142/15-12),0))/24 -> 0.31045668 | BR9: =(IF(AND(D!$FN142<180),D!$GD142+(D!$FN142/15-12),0))/24 -> 0.2198799 | BS9: =(IF(AND(D!$FP142<180),D!$GD142+(D!$FP142/15-12),0))/24 -> 0.16798239 | BT9: =D!GD142/24 -> 0.51111574 | BU9: =(BX9+(D!GG142/2)) -> 0.47500758 | BV9: =(IF(AND(D!$FS142<180),D!$GD142-(D!$FS142/15),0))/24 -> 0.22025596 | BW9: =(IF(AND(D!$FU142<180),D!$GD142-(D!$FU142/15),0))/24 -> 0.2117748 | BX9: =(IF(AND(D!$FZ142<180),D!$GD142-(D!$GB142/15),0))/24 -> 0.13955848 | BY9: =TIME(HOUR(BX9),MINUTE(BX9)-10,MINUTE(BX9)) -> 0.13217593 | BZ9: 5 | CA9: =(IF(AND(D!FC101<180),D!FG101+D!FE101/15-12,0))/24 -> 0.37786017 | CB9: =(IF(AND(D!FA101<180),D!FG101+D!FA101/15-12,0))/24 -> 0.35079581 | CC9: =TIME(HOUR(CD9),MINUTE(CD9)+3,SECOND(CD9)) -> 0.30792824 | CD9: =(IF(AND(D!$EY101<180),D!$FG101+(D!$EY101/15-12),0))/24 -> 0.30585028 | CE9: =(IF(AND(D!$ER101<180),D!$FG101+(D!$ER101/15-12),0))/24 -> 0.21547231 | CF9: =(IF(AND(D!$ET101<180),D!$FG101+(D!$ET101/15-12),0))/24 -> 0.16372078 | CG9: =D!FG101/24 -> 0.50686574 | CH9: =(CK9+(D!FK101/2)) -> 0.47086079 | CI9: =(IF(AND(D!$EW101<180),D!$FG101-(D!$EW101/15),0))/24 -> 0.21634765 | CJ9: =(IF(AND(D!$EY101<180),D!$FG101-(D!$EY101/15),0))/24 -> 0.20788121 | CK9: =(IF(AND(D!$FC101<180),D!$FG101-(D!$FE101/15),0))/24 -> 0.13587131 | CL9: =TIME(HOUR(CK9),MINUTE(CK9)-10,MINUTE(CK9)) -> 0.12864583 | CM9: 5 | CN9: =(IF(AND(D!FZ101<180),D!GD101+(D!GB101/15-12),0))/24 -> 0.3560467 | CO9: =(IF(AND(D!FX101<180),D!GD101+(D!FX101/15-12),0))/24 -> 0.33211247 | CP9: =TIME(HOUR(CQ9),MINUTE(CQ9)+3,SECOND(CQ9)) -> 0.29271991 | CQ9: =(IF(AND(D!$FU101<180),D!$GD101+(D!$FU101/15-12),0))/24 -> 0.29063944 | CR9: =(IF(AND(D!$FN101<180),D!$GD101+(D!$FN101/15-12),0))/24 -> 0.20732006 | CS9: =(IF(AND(D!$FP101<180),D!$GD101+(D!$FP101/15-12),0))/24 -> 0.16091603 | CT9: =D!GD101/24 -> 0.50553241 | CU9: =(CX9+(D!GG101/2)) -> 0.47891019 | CV9: =(IF(AND(D!$FS101<180),D!$GD101-(D!$FS101/15),0))/24 -> 0.22840479 | CW9: =(IF(AND(D!$FU101<180),D!$GD101-(D!$FU101/15),0))/24 -> 0.22042538 | CX9: =(IF(AND(D!$FZ101<180),D!$GD101-(D!$FZ101/15),0))/24 -> 0.16718093 | CY9: =TIME(HOUR(CX9),MINUTE(CX9)-10,MINUTE(CX9)) -> 0.15972222 | CZ9: 5 | DA9: =(IF(AND(D!FC55<180),D!FG55+(D!FC55/15-12),0))/24 -> 0.3233641 | DB9: =(IF(AND(D!FA55<180),D!FG55+(D!FA55/15-12),0))/24 -> 0.31279003 | DC9: =TIME(HOUR(DD9),MINUTE(DD9)+3,SECOND(DD9)) -> 0.27642361 | DD9: =(IF(AND(D!$EY55<180),D!$FG55+(D!$EY55/15-12),0))/24 -> 0.27434592 | DE9: =(IF(AND(D!$ER55<180),D!$FG55+(D!$ER55/15-12),0))/24 -> 0.1988795 | DF9: =(IF(AND(D!$ET55<180),D!$FG55+(D!$ET55/15-12),0))/24 -> 0.15907685 | DG9: =D!FG55/24 -> 0.50965741 | DH9: =(DK9+(D!FK55/2)) -> 0.47978504 | DI9: =(IF(AND(D!$EW55<180),D!$FG55-(D!$EW55/15),0))/24 -> 0.25254136 | DJ9: =(IF(AND(D!$EY55<180),D!$FG55-(D!$EY55/15),0))/24 -> 0.2449689 | DK9: =(IF(AND(D!$FC55<180),D!$FG55-(D!$FE55/15),0))/24 -> 0.18522416 | DL9: =TIME(HOUR(DK9),MINUTE(DK9)-10,MINUTE(DK9)) -> 0.1780787 | DM9: 5 | DN9: =(IF(AND(D!FZ55<180),D!GD55+D!GB55/15-12,0))/24 -> 0.31595763 | DO9: =(IF(AND(D!FX55<180),D!GD55+D!FX55/15-12,0))/24 -> 0.29495912 | DP9: =TIME(HOUR(DQ9),MINUTE(DQ9)+3,SECOND(DQ9)) -> 0.25940972 | DQ9: =(IF(AND(D!$EY55<180),D!GD55+(D!FU55/15-12),0))/24 -> 0.25733057 | DR9: =(IF(AND(D!$FN55<180),D!GD55+(D!FN55/15-12),0))/24 -> 0.18713144 | DS9: =(IF(AND(D!$FP55<180),D!GD55+(D!FP55/15-12),0))/24 -> 0.15304137 | DT9: =D!GD55/24 -> 0.51574074 | DU9: =(DX9+(D!GG55/2)) -> 0.48642721 | DV9: =(IF(AND(D!FS55<180),D!GD55-(D!FS55/15),0))/24 -> 0.28172325 | DW9: =(IF(AND(D!FU55<180),D!GD55-(D!FU55/15),0))/24 -> 0.27415091 | DX9: =(IF(AND(D!$FC55<180),D!GD55-(D!GB55/15),0))/24 -> 0.21552385 | DY9: =TIME(HOUR(DX9),MINUTE(DX9)-10,MINUTE(DX9)) -> 0.20844907 | DZ9: 5 | EA9: =(IF(AND(D!$FC10<180),D!$FG10+D!$FE10/15-12,0))/24 -> 0.29870895 | EB9: =(IF(AND(D!$FA10<180),D!$FG10+D!$FA10/15-12,0))/24 -> 0.27826248 | EC9: =TIME(HOUR(ED9),MINUTE(ED9)+3,SECOND(ED9)) -> 0.24144676 | ED9: =(IF(AND(D!$EY10<180),D!FG10+(D!EY10/15-12),0))/24 -> 0.23936873 | EE9: =(IF(AND(D!$ER10<180),D!FG10+(D!ER10/15-12),0))/24 -> 0.17104868 | EF9: =(IF(AND(D!$ET10<180),D!FG10+(D!ET10/15-12),0))/24 -> 0.14070506 | EG9: =D!FG10/24 -> 0.51749074 | EH9: =(EK9+(D!FK10/2)) -> 0.48782063 | EI9: =(IF(AND(D!EW10<180),D!FG10-(D!EW10/15),0))/24 -> 0.30358228 | EJ9: =(IF(AND(D!EY10<180),D!FG10-(D!EY10/15),0))/24 -> 0.29561275 | EK9: =(IF(AND(D!$FC10<180),D!$FG10-(D!$FE10/15),0))/24 -> 0.23627254 | EL9: =TIME(HOUR(EK9),MINUTE(EK9)-10,MINUTE(EK9)) -> 0.22962963 | EM9: 5 | EN9: =(IF(AND(D!FZ10<180),D!GD10+(D!GB10/15-12),0))/24 -> 0.28084344 | EO9: =(IF(AND(D!$FX10<180),D!$GD10+(D!$FX10/15-12),0))/24 -> 0.25969486 | EP9: =TIME(HOUR(EQ9),MINUTE(EQ9)+3,SECOND(EQ9)) -> 0.22091435 | EQ9: =(IF(AND(D!$FU10<180),D!$GD10+(D!$FU10/15-12),0))/24 -> 0.21882836 | ER9: =(IF(AND(D!$FN10<180),D!$GD10+(D!$FN10/15-12),0))/24 -> 0.15076104 | ES9: =(IF(AND(D!$FP10<180),D!$GD10+(D!$FP10/15-12),0))/24 -> 0.12279436 | ET9: =D!GD10/24 -> 0.51149074 | EU9: =(EX9+(D!GG10/2)) -> 0.4804832 | EV9: =(IF(AND(D!$FS10<180),D!$GD10-(D!$FS10/15),0))/24 -> 0.31265389 | EW9: =(IF(AND(D!$FU10<180),D!$GD10-(D!$FU10/15),0))/24 -> 0.30415313 | EX9: =(IF(AND(D!$FZ10<180),D!$GD10-(D!$GB10/15),0))/24 -> 0.24213804 | EY9: =TIME(HOUR(EX9),MINUTE(EX9)-5,MINUTE(EX9)) -> 0.23875 | EZ9: 5
